Workbook

Sheet Instruction
D1: You can enter the details in 3rd sheet with Name "Form 11 format"
A2: All Asterisk Marks (*) column should be Mandatory
A3: ROW | B3: Subject | C3: Particulars column | D3: Remarks
A4: A | B4: GEID Number* | C4: 10 digits (Only Numerical & no Alphabetical)
A5: B | B5: Name of the Employee* | C5: As per updated E-AADHAR (Download updated e-Aadhar from following website https://myaadhaar.uidai.gov.in/genricDownloadAadhaar) | D5: *Please write your name as per latest E-Aadhar card compulsorily. *Please note we will not be able to create the UAN or link your existing UAN if you do not mention your name as per latest E-Aadhar. This will have impact on your PF remittance and result into non remittance of Provident Fund for you, which will be highlighted to Citi Governance team and your Business Unit Head as statutory breach.
A6: C | B6: Father / Husband Name* | C6: Father Name as per E-Aadhar card & Spouse Name – Only Applicable for Married Women | D6: Even if your Father/Husband Name is not mentioned in Aadhar, then also its mandatory to mention the Father/Husband name
A7: D | B7: RELATIONSHIP (FATHER / HUSBAND)*
A8: E | B8: Marital Status* | C8: Single / Married / Divorcee / Widower
A9: F,G,H | B9: Date of Birth (dd/mm/yy)* | C9: DOB as per (dd/mm/yyyy) format - as per E-Aadhar card | D9: Please Download updated e-Aadhaar from following website https://myaadhaar.uidai.gov.in/genricDownloadAadhaar and follow below notes to avoid non remittance. *Please write your date of Birth as per latest E-Aadhar card compulsorily. *Please note we will not be able to create the UAN or link your existing UAN if you do not mention your date of birth as per latest E-Aadhar. This will have impact on your PF remittance and result into non remittance of Provident Fund for you, which will be highlighted to Citi Governance team and your Business Unit Head as statutory breach.
A10: I, J, K | B10: Date of Joining (dd/mm/yy)* | C10: As per Citi record (dd/mm/yyyy) format | D10: Please follow below note:- *Please note if DOJ declared by you in form 11 mismatched with payroll DOJ, your DOJ with payroll will be deemed final DOJ to update in EPFO system since salary and benefit processing are done based on payroll records
A11: L | B11: Whether Earlier A Member Of Employees Provident Fund Scheme (Y/N)* | C11: Please follow below note:- If your Previous company was deducting Provident fund (PF) from your salary then select “Yes” – if Not then select "No". Please do check your previous pay slip for correct information while filling up the details. | D11: Please note ,If you provide incorrect information , then Citi as employer will not be accountable for future repercussions on your PF transfer in and out , PF withdrawal , hence make sure correct details are filled in before submitting form with us.
A12: M | B12: Whether Earlier A Member Of Employees Pension Scheme, 1995 (Y/N)* | C12: Please refer below notes carefully as most of the employee make mistake in this section:- 1- If you have withdrawn your PF & Pension both with previous employer and declared same UAN with Citi to start PF deduction, then select "NO" compulsorily 2. If your Previous company was deducting pension (EPS) under this scheme then "YES" else "No". Note : Download EPF passbook from PF portal and check the previous EPS status from below web link' "https://passbook.epfindia.gov.in/Member Passbook/Login" | D12: Please note ,If you provide incorrect information , then Citi as employer will not be accountable for future repercussions on your PF & EPS transfer in and out , PF & Pension withdrawal , hence make sure correct details are filled in before submitting form with us. Note : Download EPF passbook from PF portal and check the previous EPS status from below web link' "https://passbook.epfindia.gov.in/Member Passbook/Login" and submit the details accordingly
A13: N | B13: UAN NUMBER* | C13: If you have a UAN from your previous employment - Please enter the 12-digit UAN exactly as mentioned in your previous employer’s pay slip. OR If you are a first-time EPFO member - Generate a new UAN – refer to the sheet "UAN_Process" for step-by-step instructions. Note: Do not generate a UAN if you fall under the International Worker (IW) category - holding passport other than Indian | D13: Please follow below note:- As per new EPFO rules effective 1st August 2025, all new employees who are registering with EPFO for the first time must generate their own UAN. The employer can no longer create UANs for employees. Please follow the steps in the next sheet (UAN_process) to generate your UAN using your Aadhaar and mobile number. *Please note if you don't provide us UAN, it will have impact on your PF remittance and result into non remittance of Provident Fund for you, which will be highlighted to Citi Governance team and your Business Unit Head as statutory breach.
A14: O | B14: PAN Card Number* | C14: 10 Alphabetics and Numerical Digits, After enter the PAN number pls check the column "AD" status. | D14: Please follow below note:- First 5 are alphabets then next 4 are numeric and last one is alphabet. The remark would appear in AD column “ PAN_VALIDATION “.
A15: P | B15: Aadhar card Number* | C15: 12 Numerical Digits to be mentioned - (you will get from previous employer Salary Slip) if applicable. | D15: Please follow below note:- *Please note we will not be able to create the UAN or link your existing UAN if you do not mention your Aadhar number as per latest E-Aadhar. This will have impact on your PF remittance and result into non remittance of Provident Fund for you, which will be highlighted to Citi Governance team and your Business Unit Head as statutory breach. Download updated e-Aadhaar from following website https://myaadhaar.uidai.gov.in/genricDownloadAadhaar
A16: Q | B16: Mobile Number* | C16: 10 Numerical Digits - Number should be linked with E Aadhar card and PAN | D16: Number should be linked with Aadhar card, as you will receive the OTP while doing any activity in the PF portal.
A17: R | B17: International Worker (Y/N)* | C17: 1. If you are holding Indian passport with nationality as “INDIAN” then select “NO” 2. If you are not holding any passport and you are citizen of India then select “NO” 3. If you are holding other than Indian country passport and nationality is other than “INDIAN” then select “YES” | D17: if " Yes "Please do share your passport and OCI copy on email along with excel form 11 format, else your form 11 will be rejected by HGS team without information
A18: S | B18: Nationality* | C18: If it is YES then require following all upcoming details mention in the excel sheet.
A19: T | B19: Passport Number
A20: U | B20: Passport Issuing Country
A21: V | B21: Passport Valid From (dd/mm/yy)
A22: W | B22: Passport Valid Till (dd/mm/yy)
A23: X | B23: Visa Issusing Country
A24: Y | B24: Visa Valid From (dd/mm/yy)
A25: Z | B25: Visa Valid Till (dd/mm/yy)
A26: AA | B26: Name Of The Coutry Mentioned In The Passport
G30: Country | H30: Nationality
G31: Afghanistan | H31: Afghan
G32: Albania | H32: Albanian
G33: Algeria | H33: Algerian
G34: Andorra | H34: Andorran
G35: Angola | H35: Angolan
G36: Argentina | H36: Argentine / Argentinian
G37: Armenia | H37: Armenian
G38: Australia | H38: Australian
G39: Austria | H39: Austrian
G40: Azerbaijan | H40: Azerbaijani
G41: Bahamas | H41: Bahamian
... G184: Zimbabwe | H184: Zimbabwean

Sheet UAN_Process
B2: STEPS TO GENERATE/ACTIVATE UAN THROUGH UMANG APP | D2: STEPS FOR EXISITNG UAN ACTIVATION THROUGH EPFO PORTAL
B4: Mandatory Things & Apps – Before starting: | D4: Mandatory Things – Before starting:
B5: · Smartphone with internet | D5: · Laptop / Desktop / Smartphone with internet
B6: · UMANG App installed (from Play Store or App Store) | D6: · Aadhaar-linked mobile number
B7: · Aadhaar Face RD App installed
B8: · Aadhaar-linked mobile number
B10: Step-by-Step Process: | D10: Step-by-Step Process:
B11: · Open UMANG App | D11: · Visit EPFO portal
B12: · Search for “EPFO” in the app. | D12: https://unifiedportal-mem.epfindia.gov.in/memberinterface/
B13: · Select “UAN Allotment and Activation”. | D13: · Select “Know your UAN"
B14: · Enter Aadhaar Details & mobile number linked with Aadhaar. | D14: · Enter the mobile number linked with Aadhar and the Captcha code - generate OTP
B15: · Generate & Enter OTP (accept the consent checkbox) - Submit | D15: · Enter the OTP and Captcha again - Submit
B16: · The app will redirect to the Aadhaar Face RD App. | D16: · Enter Details as per Aadhar: Name, DOB
B17: · Look into the camera to complete face scan. | D17: · Select from Aadhar/PAN/Member ID
B18: · If no UAN exists for your Aadhaar, a new UAN will be allotted, | D18: · Enter the selected ID number (e.g., Aadhaar number if Aadhaar is selected).
B19: · and You’ll receive the UAN via SMS on your registered mobile number. | D19: · Enter Captcha code and Submit
D20: · Your UAN will be shown on the Screen
B22: Existing UAN Activation (Not Activate Yet) | D22: Update KYC, E-NOMINATION to EPFO portal
B23: · Select “UAN Activation” | D23: · Visit EPFO portal
B24: · Provide UAN, Aadhaar, and mobile number | D24: https://unifiedportal-mem.epfindia.gov.in/memberinterface/
B25: · Consent → OTP → Face scan | D25: · Use your UAN and temporary password to log in.
B26: · You will receive a temporary password via SMS; | D26: · Update your password and profile.
B27: · Your UAN is activated and your EPFO profile (photo & address) gets updated | D27: · Add or Update KYC details (Bank, PAN or Passport)
D28: · Complete E-Nomination or else UAN may block as per EPFO rules.
B29: Note: If the above process is not working on iOS mobile, please try using an Android mobile device. | D29: Note: If the above process is not working on iOS mobile, please try using an Android mobile device.

Sheet Form 11 Format
A1: Before updating the below form 11 details, please go through to the notes which is in next sheet.
A2: =IF(MAX(LEN(A5),0)=0,"P",1) -> 1 | B2: =IF(MAX(LEN(B5),0)=0,"P",1) -> 1 | C2: =IF(MAX(LEN(C5),0)=0,"P",1) -> 1 | D2: =IF(MAX(LEN(D5),0)=0,"P",1) -> 1 | E2: =IF(MAX(LEN(E5),0)=0,"P",1) -> 1 | F2: =IF(MAX(LEN(F5),0)=0,"P",1) -> 1 | G2: =IF(MAX(LEN(G5),0)=0,"P",1) -> 1 | H2: =IF(MAX(LEN(H5),0)=0,"P",1) -> 1 | ... M2: =IF(MAX(LEN(M5),0)=0,"P",1) -> 1 | O2: =IF(MAX(LEN(O5),0)=0,"P",1) -> 1 | P2: =IF(MAX(LEN(P5),0)=0,"P",1) -> 1 | Q2: =IF(MAX(LEN(Q5),0)=0,"P",1) -> 1 | R2: =IF(MAX(LEN(R5),0)=0,"P",1) -> 1 | S2: =IF(MAX(LEN(S5),0)=0,"P",1) -> 1
A3: =UPPER(IF(LEN(A5)>0,"Err - Mandatory field - "&HLOOKUP("P",B2:AA4,3,0),"")) -> #N/A | F3: Date of Birth | I3: Date of Joining CSIPL
A4: GEID* (10 Digits) | B4: NAME OF EMPLOYEE * | C4: FATHER / HUSBAND NAME* (Any one) | D4: RELATIONSHIP (FATHER / HUSBAND)* | E4: MARITAL STATUS* | F4: DD* | G4: MM* | H4: YYYY* | I4: DD* | J4: MM* | K4: YYYY* | L4: WHETHER EARLIER A MEMBER OF EMPLOYEES PROVIDENT FUND SCHEME- YES/NO* | M4: WHETHER EARLIER A MEMBER OF EMPLOYEES' PENSION SCHEME, 1995 * | N4: UAN NUMBER* | O4: PAN NUMBER* | P4: AADHAR NUMBER* | Q4: MOBILE NUMBER | R4: INTERNATIONAL WORKER -YES/NO* | S4: NATIONALITY * | T4: PASSPORT NO. | U4: PASSPORT ISSUING COUNTRY | V4: PASSPORT VALID FROM (DD/MM/YYYY) | W4: PASSPORT VALID TILL (DD/MM/YYYY) | X4: VISA ISSUING COUNTRY | Y4: VISA VALID FROM (DD/MM/YYYY) | Z4: VISA VALID TILL (DD/MM/YYYY) | AA4: NAME OF THE COUTRY MENTIONED IN THE PASSPORT | AC4: PAN_VALIDATION
A5: 1011558376 | B5: Nisha Nikhil Kadam | C5: Nikhil Maruti Kadam | D5: Husband | E5: Married | F5: 17 | G5: 7 | H5: 1996 | I5: 5 | J5: 10 | K5: 2026 | L5: Yes | M5: No | N5: 101006584039 | O5: CRDPM5687D | P5: 474820507890 | Q5: 9130721182 | R5: No | S5: Indian | AC5: =IF(AND(ISERROR(SUM(LEFT(O5,1))),ISERROR(SUM(MID(O5,2,1))),ISERROR(SUM(MID(O5,3,1))),ISERROR(SUM(MID(O5,4,1))),ISERROR(SUM(MID(O5,5,1))),ISNUMBER(SUM(MID(O5,6,1),MID(O5,7,1),MID(O5,8,1),MID(O5,9,1))),ISERROR(SUM(RIGHT(O5,1)))),"OK","CHECK") -> OK
B6: * Name as per E-Aadhaar Please refer notes tab row 5 | F6: *Please refer notes tab row 9 | I6: *Please refer notes tab row 10 ******** Enter date of joining with citi | L6: *Please refer notes tab row 11 | M6: *Please refer notes tab row 12 (Pension eligibility Check) | N6: *Please refer notes tab row 13 | O6: First 5 are alphabets then next 4 are numeric and last one is alphabet. The remark would appear in AD column “ PAN_VALIDATION “. If this is ok then proceed | P6: *Please refer notes tab row 15 | Q6: *Please refer notes tab row 16 | R6: *Please refer notes tab row 17 | S6: *Please refer notes tab row 18 * If nationality is other than Indian, please share passport & OCI copy and fill details in coumn from T to AA | T6: *If nationality Is other than Indian then above column should be mandatory* Please share a copy of the international passport and OCI (if available) with us Do not generate a NEW UAN if you are holding an International Passport
AM78: Composite Declaration Form-11
AM79: (To be retained by the employer for future reference)
AM80: EMPLOYEES' PROVIDENT FUND ORGANISATION
AM81: Employees' Provident Funds scheme, 1952 (Paragraph 34 & 57) &
AM82: Employees' Pension Scheme, 1995 (Paragraph 24)
AM83: (Declaration by a person taking up employment in any establishment on which EPF Scheme, 1952 and/or EPS, 1995 is applicable)
AS85: GEID: | AT85: =IF('Form 11 Format'!$A$5="","",'Form 11 Format'!$A$5) -> 1011558376
AM86: 1 | AN86: Name of the member | AS86: =IF('Form 11 Format'!$B$5="","",UPPER('Form 11 Format'!$B$5)) -> NISHA NIKHIL KADAM
AN87: Father's Name | AS87: {=_xlfn.SWITCH(TRUE(),('Form 11 Format'!$D$5)="Father",('Form 11 Format'!$C$5),"")}
AN88: Spouse's Name | AS88: {=_xlfn.SWITCH(TRUE(),('Form 11 Format'!$D$5)="Husband",('Form 11 Format'!$C$5),"")} -> Nikhil Maruti Kadam
AM89: 3 | AN89: Date of Birth: (DD/MM/YYYY) | AS89: ='Form 11 Format'!$F$5&"-"&'Form 11 Format'!$G$5&"-"&'Form 11 Format'!$H$5 -> 17-7-1996
AM90: 4 | AN90: Gender: (Male/Female/Transgender)
AM91: 5 | AN91: Marital Status: (Married/Unmarried/Widow/Widower/Divorcee) | AS91: =UPPER('Form 11 Format'!$E$5) -> MARRIED
AM92: 6 | AN92: (a) Email ID:
AN93: (b) Mobile No.: | AS93: =IF('Form 11 Format'!$Q$5="","",'Form 11 Format'!$Q$5) -> 9130721182
AM94: 7 | AN94: Present employment details:
AN95: Date of joining in the current establishment (DD/MM/YYYY) | AS95: ='Form 11 Format'!$I$5&"-"&'Form 11 Format'!$J$5&"-"&'Form 11 Format'!$K$5 -> 5-10-2026
AM96: 8 | AN96: KYC Details: (attach self attested copies of following KYCs)
AN97: a) Bank Account No.:
AN98: b) IFSC Code of the branch:
AN99: c) AADHAR Number | AS99: =IF('Form 11 Format'!$P$5="","",'Form 11 Format'!$P$5) -> 474820507890
AN100: d) Permanent Account Number (PAN), if available | AS100: =UPPER('Form 11 Format'!$O$5) -> CRDPM5687D
AM101: 9 | AN101: Whether earlier a member of Employees' Provident Fund Scheme, 1952. | AS101: =IF('Form 11 Format'!$L$5="","",'Form 11 Format'!$L$5) -> Yes
AM102: 10 | AN102: Whether earlier a member of Employees' Pension Scheme, 1995 | AS102: =IF('Form 11 Format'!$M$5="","",'Form 11 Format'!$M$5) -> No
AM103: 11 | AN103: Previous employment details: [if Yes to 9 AND/OR 10 above] - Un-exempted
AO104: Establishment Name & Address | AP104: Universal Account Number | AQ104: PF Account Number | AR104: Date of joining (DD/MM/YYYY) | AS104: Date of exit (DD/MM/YYYY) | AT104: Scheme Certificate No. (if issued) | AU104: PPO Number (if issued) | AV104: Non Contributory Period (NCP) Days
AM107: 12 | AN107: Previous employment details: [if Yes to 9 AND/OR 10 above] - exempted Trusts
AO108: Name & Address of the Trust | AQ108: Universal Account Number | AR108: Member EPS A/c Number | AS108: Date of joining (DD/MM/YYYY) | AT108: Date of exit (DD/MM/YYYY) | AU108: Scheme Certificate No. (if issued) | AV108: Non Contributory Period (NCP) Days
AM111: 13 | AN111: a) International Worker: (YES/NO) | AS111: =IF('Form 11 Format'!$R$5="","",'Form 11 Format'!$R$5) -> No
AN112: b) if Yes, State country of origin (India/Name of other Country) | AS112: =IF('Form 11 Format'!$AA$5="","",'Form 11 Format'!$AA$5)
AN113: c) Passport Number | AS113: =IF('Form 11 Format'!$T$5="","",'Form 11 Format'!$T$5)
AN114: d) Validity of passport [(DD/MM/YYYY) to (DD/MM/YYYY)] | AS114: =IF('Form 11 Format'!$V$5="","",'Form 11 Format'!$V$5&" TO "&'Form 11 Format'!$W$5)
AM118: UNDERTAKING
AM119: 1) Certified that the particulars are true to the best of my knowledge.
...

Sheet PDFFORM
A1: Composite Declaration Form-11
A2: (To be retained by the employer for future reference)
A3: EMPLOYEES' PROVIDENT FUND ORGANISATION
A4: Employees' Provident Funds scheme, 1952 (Paragraph 34 & 57) &
A5: Employees' Pension Scheme, 1995 (Paragraph 24)
A6: (Declaration by a person taking up employment in any establishment on which EPF Scheme, 1952 and/or EPS, 1995 is applicable)
G8: GEID: | H8: =IF('Form 11 Format'!A5="","",'Form 11 Format'!A5) -> 1011558376
A9: 1 | B9: Name of the member | G9: =IF('Form 11 Format'!B5="","",UPPER('Form 11 Format'!B5)) -> NISHA NIKHIL KADAM
B10: Father's Name | G10: {=_xlfn.SWITCH(TRUE(),('Form 11 Format'!$D$5)="Father",('Form 11 Format'!$C$5),"")}
B11: Spouse's Name | G11: {=_xlfn.SWITCH(TRUE(),('Form 11 Format'!$D$5)="Husband",('Form 11 Format'!$C$5),"")} -> Nikhil Maruti Kadam
A12: 3 | B12: Date of Birth: (DD/MM/YYYY) | G12: ='Form 11 Format'!F5&"-"&'Form 11 Format'!G5&"-"&'Form 11 Format'!H5 -> 17-7-1996
A13: 4 | B13: Gender: (Male/Female/Transgender)
A14: 5 | B14: Marital Status: (Married/Unmarried/Widow/Widower/Divorcee) | G14: =UPPER('Form 11 Format'!E5) -> MARRIED
A15: 6 | B15: (a) Email ID:
B16: (b) Mobile No.: | G16: =IF('Form 11 Format'!Q5="","",'Form 11 Format'!Q5) -> 9130721182
A17: 7 | B17: Present employment details:
B18: Date of joining in the current establishment (DD/MM/YYYY) | G18: ='Form 11 Format'!I5&"-"&'Form 11 Format'!J5&"-"&'Form 11 Format'!K5 -> 5-10-2026
A19: 8 | B19: KYC Details: (attach self attested copies of following KYCs)
B20: a) Bank Account No.:
B21: b) IFSC Code of the branch:
B22: c) AADHAR Number | G22: =IF('Form 11 Format'!P5="","",'Form 11 Format'!P5) -> 474820507890
B23: d) Permanent Account Number (PAN), if available | G23: =UPPER('Form 11 Format'!O5) -> CRDPM5687D
A24: 9 | B24: Whether earlier a member of Employees' Provident Fund Scheme, 1952. | G24: =IF('Form 11 Format'!L5="","",'Form 11 Format'!L5) -> Yes
A25: 10 | B25: Whether earlier a member of Employees' Pension Scheme, 1995 | G25: =IF('Form 11 Format'!M5="","",'Form 11 Format'!M5) -> No
A26: 11 | B26: Previous employment details: [if Yes to 9 AND/OR 10 above] - Un-exempted
C27: Establishment Name & Address | D27: Universal Account Number | E27: PF Account Number | F27: Date of joining (DD/MM/YYYY) | G27: Date of exit (DD/MM/YYYY) | H27: Scheme Certificate No. (if issued) | I27: PPO Number (if issued) | J27: Non Contributory Period (NCP) Days
A30: 12 | B30: Previous employment details: [if Yes to 9 AND/OR 10 above] - exempted Trusts
C31: Name & Address of the Trust | E31: Universal Account Number | F31: Member EPS A/c Number | G31: Date of joining (DD/MM/YYYY) | H31: Date of exit (DD/MM/YYYY) | I31: Scheme Certificate No. (if issued) | J31: Non Contributory Period (NCP) Days
A34: 13 | B34: a) International Worker: (YES/NO) | G34: =IF('Form 11 Format'!R5="","",'Form 11 Format'!R5) -> No
B35: b) if Yes, State country of origin (India/Name of other Country) | G35: =IF('Form 11 Format'!AA5="","",'Form 11 Format'!AA5)
B36: c) Passport Number | G36: =IF('Form 11 Format'!T5="","",'Form 11 Format'!T5)
B37: d) Validity of passport [(DD/MM/YYYY) to (DD/MM/YYYY)] | G37: =IF('Form 11 Format'!V5="","",'Form 11 Format'!V5&" TO "&'Form 11 Format'!W5)
A41: UNDERTAKING
A42: 1) Certified that the particulars are true to the best of my knowledge.
A43: 2) I authorize EPFO to use my Aadhar for verification/authentication/e-KYC purpose for service delivery.
A44: 3) Kindly transfer the funds and service details, if applicable, from the previous PF account as declared above to the present P.F. account as I am an Aadhar verified employee in my previous PF Account.*
A45: 4) In case of changes in above details, the same will be intimated to employer at the earliest.
A50: Date:
A51: Place: | H51: Signature of Member
H52: =(G9) -> NISHA NIKHIL KADAM
...
